Workbook

Sheet Apple
A1: Date | B1: Adj Close | C1: Return | D1: Return +1 | E1: start 16.23
A2: 44197 | B2: 128817429
A3: 44204 | B3: 126839706 | C3: =(B3-B2)/B2 -> -0.015352915 | D3: =C3+1 -> 0.98464709
A4: 44211 | B4: 134671875 | C4: =(B4-B3)/B3 -> 0.061748558 | D4: =C4+1 -> 1.0617486
A5: 44218 | B5: 134888336 | C5: =(B5-B4)/B4 -> 0.0016073215 | D5: =C5+1 -> 1.0016073
A6: 44225 | B6: 135183533 | C6: =(B6-B5)/B5 -> 0.0021884546 | D6: =C6+1 -> 1.0021885
A7: 44232 | B7: 132959824 | C7: =(B7-B6)/B6 -> -0.016449555 | D7: =C7+1 -> 0.98355044
A8: 44239 | B8: 127817604 | C8: =(B8-B7)/B7 -> -0.038674991 | D8: =C8+1 -> 0.96132501
A9: 44246 | B9: 119224815 | C9: =(B9-B8)/B8 -> -0.06722696 | D9: =C9+1 -> 0.93277304
A10: 44253 | B10: 118377350 | C10: =(B10-B9)/B9 -> -0.0071081259 | D10: =C10+1 -> 0.99289187
A11: 44260 | B11: 120180672 | C11: =(B11-B10)/B10 -> 0.015233674 | D11: =C11+1 -> 1.0152337
A12: 44267 | B12: 118771530 | C12: =(B12-B11)/B11 -> -0.011725197 | D12: =C12+1 -> 0.9882748
A13: 44274 | B13: 118830643 | C13: =(B13-B12)/B12 -> 0.00049770345 | D13: =C13+1 -> 1.0004977
A14: 44281 | B14: 121205490 | C14: =(B14-B13)/B13 -> 0.01998514 | D14: =C14+1 -> 1.0199851
... A106: 44925 | B106: 129378006 | C106: =(B106-B105)/B105 -> 0.0024688947 | D106: =C106+1 -> 1.0024689
A107: Arithmatic return | C107: =AVERAGE(C3:C106) -> 0.00069060916
A108: Geometric return | D108: =GEOMEAN(D3:D106)-1 -> 4.1753523e-05
A109: STD return | C109: =_xlfn.STDEV.S(C3:C106) -> 0.036205383
A110: Variance return | C110: =_xlfn.VAR.S(C3:C106) -> 0.0013108298

Sheet Tesla
A1: Date | B1: Adj Close | C1: Return | D1: Return +1
A2: 44197 | B2: 272013336
A3: 44204 | B3: 281666656 | C3: =(B3-B2)/B2 -> 0.035488407 | D3: =C3+1 -> 1.0354884
A4: 44211 | B4: 281663330 | C4: =(B4-B3)/B3 -> -1.1808284e-05 | D4: =C4+1 -> 0.99998819
A5: 44218 | B5: 278476654 | C5: =(B5-B4)/B4 -> -0.011313777 | D5: =C5+1 -> 0.98868622
A6: 44225 | B6: 283329987 | C6: =(B6-B5)/B5 -> 0.01742815 | D6: =C6+1 -> 1.0174282
A7: 44232 | B7: 270553345 | C7: =(B7-B6)/B6 -> -0.045094563 | D7: =C7+1 -> 0.95490544
A8: 44239 | B8: 262459991 | C8: =(B8-B7)/B7 -> -0.029914078 | D8: =C8+1 -> 0.97008592
A9: 44246 | B9: 227406662 | C9: =(B9-B8)/B8 -> -0.13355685 | D9: =C9+1 -> 0.86644315
A10: 44253 | B10: 207146667 | C10: =(B10-B9)/B9 -> -0.089091475 | D10: =C10+1 -> 0.91090852
A11: 44260 | B11: 233199997 | C11: =(B11-B10)/B10 -> 0.12577238 | D11: =C11+1 -> 1.1257724
A12: 44267 | B12: 217720001 | C12: =(B12-B11)/B11 -> -0.066380773 | D12: =C12+1 -> 0.93361923
A13: 44274 | B13: 213463333 | C13: =(B13-B12)/B12 -> -0.019551111 | D13: =C13+1 -> 0.98044889
A14: 44281 | B14: 220583328 | C14: =(B14-B13)/B13 -> 0.033354651 | D14: =C14+1 -> 1.0333547
... A106: 44925 | B106: 123180000 | C106: =(B106-B105)/B105 -> 0.011164012 | D106: =C106+1 -> 1.011164
A107: Arithmatic return | C107: =AVERAGE(C3:C106) -> -0.0046737314
A108: Geometric return | D108: =GEOMEAN(D3:D106)-1 -> -0.0075884115
A109: STD return | C109: =_xlfn.STDEV.S(C3:C106) -> 0.076303517
A110: Variance return | C110: =_xlfn.VAR.S(C3:C106) -> 0.0058222267

Sheet Nike
A1: Date | B1: Adj Close | C1: Return | D1: Return +1
A2: 44197 | B2: 140995590
A3: 44204 | B3: 137445206 | C3: =(B3-B2)/B2 -> -0.025180816 | D3: =C3+1 -> 0.97481918
A4: 44211 | B4: 137746719 | C4: =(B4-B3)/B3 -> 0.002193696 | D4: =C4+1 -> 1.0021937
A5: 44218 | B5: 131044693 | C5: =(B5-B4)/B4 -> -0.048654705 | D5: =C5+1 -> 0.95134529
A6: 44225 | B6: 136793472 | C6: =(B6-B5)/B5 -> 0.043868843 | D6: =C6+1 -> 1.0438688
A7: 44232 | B7: 139624084 | C7: =(B7-B6)/B6 -> 0.020692596 | D7: =C7+1 -> 1.0206926
A8: 44239 | B8: 141131805 | C8: =(B8-B7)/B7 -> 0.010798431 | D8: =C8+1 -> 1.0107984
A9: 44246 | B9: 131842316 | C9: =(B9-B8)/B8 -> -0.065821372 | D9: =C9+1 -> 0.93417863
A10: 44253 | B10: 128437790 | C10: =(B10-B9)/B9 -> -0.025822711 | D10: =C10+1 -> 0.97417729
A11: 44260 | B11: 137617432 | C11: =(B11-B10)/B10 -> 0.071471504 | D11: =C11+1 -> 1.0714715
A12: 44267 | B12: 139547287 | C12: =(B12-B11)/B11 -> 0.014023332 | D12: =C12+1 -> 1.0140233
A13: 44274 | B13: 125384964 | C13: =(B13-B12)/B12 -> -0.10148763 | D13: =C13+1 -> 0.89851237
A14: 44281 | B14: 129176544 | C14: =(B14-B13)/B13 -> 0.030239511 | D14: =C14+1 -> 1.0302395
... A106: 44925 | B106: 115905754 | C106: =(B106-B105)/B105 -> -0.0028973213 | D106: =C106+1 -> 0.99710268
A107: Arithmatic return | C107: =AVERAGE(C3:C106) -> -0.00090638804
A108: Geometric return | D108: =GEOMEAN(D3:D106)-1 -> -0.0018823724
A109: STD return | C109: =_xlfn.STDEV.S(C3:C106) -> 0.04464594
A110: Variance return | C110: =_xlfn.VAR.S(C3:C106) -> 0.0019932599

Sheet Walmart
A1: Date | B1: Adj Close | C1: Return | D1: Return +1
A2: 44197 | B2: 140505096
A3: 44204 | B3: 140811722 | C3: =(B3-B2)/B2 -> 0.0021823123 | D3: =C3+1 -> 1.0021823
A4: 44211 | B4: 138780548 | C4: =(B4-B3)/B3 -> -0.014424751 | D4: =C4+1 -> 0.98557525
A5: 44218 | B5: 137726639 | C5: =(B5-B4)/B4 -> -0.0075940686 | D5: =C5+1 -> 0.99240593
A6: 44225 | B6: 136557755 | C6: =(B6-B5)/B5 -> -0.0084869856 | D6: =C6+1 -> 0.99151301
A7: 44232 | B7: 137985321 | C7: =(B7-B6)/B6 -> 0.010453936 | D7: =C7+1 -> 1.0104539
A8: 44239 | B8: 131891800 | C8: =(B8-B7)/B7 -> -0.044160647 | D8: =C8+1 -> 0.95583935
A9: 44246 | B9: 126421074 | C9: =(B9-B8)/B8 -> -0.041478894 | D9: =C9+1 -> 0.95852111
A10: 44253 | B10: 122186279 | C10: =(B10-B9)/B9 -> -0.03349754 | D10: =C10+1 -> 0.96650246
A11: 44260 | B11: 126593529 | C11: =(B11-B10)/B10 -> 0.036069926 | D11: =C11+1 -> 1.0360699
A12: 44267 | B12: 124562370 | C12: =(B12-B11)/B11 -> -0.01604473 | D12: =C12+1 -> 0.98395527
A13: 44274 | B13: 128930817 | C13: =(B13-B12)/B12 -> 0.035070359 | D13: =C13+1 -> 1.0350704
A14: 44281 | B14: 130479828 | C14: =(B14-B13)/B13 -> 0.01201428 | D14: =C14+1 -> 1.0120143
... A106: 44925 | B106: 140178497 | C106: =(B106-B105)/B105 -> -0.0025325613 | D106: =C106+1 -> 0.99746744
A107: Arithmatic return | C107: =AVERAGE(C3:C106) -> 0.00051968195
A108: Geometric return | D108: =GEOMEAN(D3:D106)-1 -> -2.2376379e-05
A109: STD return | C109: =_xlfn.STDEV.S(C3:C106) -> 0.032298017
A110: Variance return | C110: =_xlfn.VAR.S(C3:C106) -> 0.0010431619

Sheet Exxon
A1: Date | B1: Adj Close | C1: Return | D1: Return +1
A2: 44197 | B2: 39754604
A3: 44204 | B3: 44485188 | C3: =(B3-B2)/B2 -> 0.11899462 | D3: =C3+1 -> 1.1189946
A4: 44211 | B4: 42539906 | C4: =(B4-B3)/B3 -> -0.043728758 | D4: =C4+1 -> 0.95627124
A5: 44218 | B5: 40727249 | C5: =(B5-B4)/B4 -> -0.042610743 | D5: =C5+1 -> 0.95738926
A6: 44225 | B6: 42734440 | C6: =(B6-B5)/B5 -> 0.049283736 | D6: =C6+1 -> 1.0492837
A7: 44232 | B7: 44069607 | C7: =(B7-B6)/B6 -> 0.031243348 | D7: =C7+1 -> 1.0312433
A8: 44239 | B8: 46778347 | C8: =(B8-B7)/B7 -> 0.061465036 | D8: =C8+1 -> 1.061465
A9: 44246 | B9: 50141499 | C9: =(B9-B8)/B8 -> 0.071895486 | D9: =C9+1 -> 1.0718955
A10: 44253 | B10: 52794250 | C10: =(B10-B9)/B9 -> 0.052905299 | D10: =C10+1 -> 1.0529053
A11: 44260 | B11: 55132271 | C11: =(B11-B10)/B10 -> 0.044285524 | D11: =C11+1 -> 1.0442855
A12: 44267 | B12: 51085697 | C12: =(B12-B11)/B11 -> -0.073397557 | D12: =C12+1 -> 0.92660244
A13: 44274 | B13: 50519176 | C13: =(B13-B12)/B12 -> -0.011089621 | D13: =C13+1 -> 0.98891038
A14: 44281 | B14: 51607246 | C14: =(B14-B13)/B13 -> 0.021537762 | D14: =C14+1 -> 1.0215378
... A106: 44925 | B106: 107633774 | C106: =(B106-B105)/B105 -> 0.010073258 | D106: =C106+1 -> 1.0100733
A107: Arithmatic return | C107: =AVERAGE(C3:C106) -> 0.010523263
A108: Geometric return | D108: =GEOMEAN(D3:D106)-1 -> 0.0096230142
A109: STD return | C109: =_xlfn.STDEV.S(C3:C106) -> 0.042905201
A110: Variance return | C110: =_xlfn.VAR.S(C3:C106) -> 0.0018408562

Sheet Portfolio
A13: Tabel Portfolio
B14: Apple | C14: Tesla | D14: Nike | E14: Walmart | F14: Exxon
A15: Expected Return | B15: =Apple!D108 -> 4.1753523e-05 | C15: =Tesla!D108 -> -0.0075884115 | D15: =Nike!D108 -> -0.0018823724 | E15: =Walmart!D108 -> -2.2376379e-05 | F15: =Exxon!D108 -> 0.0096230142
A16: Standard Deviation | B16: =Apple!C109 -> 0.036205383 | C16: =Tesla!C109 -> 0.076303517 | D16: =Nike!C109 -> 0.04464594 | E16: =Walmart!C109 -> 0.032298017 | F16: =Exxon!C109 -> 0.042905201
A17: Shares Hold | B17: 0.2 | C17: 0.2 | D17: 0.2 | E17: 0.2 | F17: 0.2
A19: Expected Return x Shares Hold | B19: =B15*B17 -> 8.3507045e-06 | C19: =C15*C17 -> -0.0015176823 | D19: =D15*D17 -> -0.00037647449 | E19: =E15*E17 -> -4.4752759e-06 | F19: =F15*F17 -> 0.0019246028
A20: Portfolio Expected Return | B20: =SUM(B19:F19) -> 3.4321494e-05
A23: Tabel Covariansi Antar Return Saham (Mingguan)
B24: Apple | C24: Tesla | D24: Nike | E24: Walmart | F24: Exxon
A25: Apple | B25: 1 | C25: =_xlfn.COVARIANCE.S(Apple!C3:C106,Tesla!C3:C106) -> 0.001502641 | D25: =_xlfn.COVARIANCE.S(Apple!C3:C106,Nike!C3:C106) -> 0.00080452879 | E25: =_xlfn.COVARIANCE.S(Apple!C3:C106,Walmart!C3:C106) -> 0.00044525451 | F25: =_xlfn.COVARIANCE.S(Apple!C3:C106,Exxon!C3:C106) -> 2.8782196e-05
A26: Tesla | B26: =_xlfn.COVARIANCE.S(Apple!C3:C106,Tesla!C3:C106) -> 0.001502641 | C26: 1 | D26: =_xlfn.COVARIANCE.S(Tesla!C3:C106,Nike!C3:C106) -> 0.0013144538 | E26: =_xlfn.COVARIANCE.S(Tesla!C3:C106,Walmart!C3:C106) -> 0.00070522851 | F26: =_xlfn.COVARIANCE.S(Tesla!C3:C106,Exxon!C3:C106) -> 0.00029010547
A27: Nike | B27: =_xlfn.COVARIANCE.S(Apple!C3:C106,Nike!C3:C106) -> 0.00080452879 | C27: =_xlfn.COVARIANCE.S(Tesla!C3:C106,Nike!C3:C106) -> 0.0013144538 | D27: 1 | E27: =_xlfn.COVARIANCE.S(Nike!C3:C106,Walmart!C3:C106) -> 0.00036035667 | F27: =_xlfn.COVARIANCE.S(Nike!C3:C106,Exxon!C3:C106) -> 6.4783365e-05
A28: Walmart | B28: =_xlfn.COVARIANCE.S(Apple!C3:C106,Walmart!C3:C106) -> 0.00044525451 | C28: =_xlfn.COVARIANCE.S(Tesla!C3:C106,Walmart!C3:C106) -> 0.00070522851 | D28: =_xlfn.COVARIANCE.S(Nike!C3:C106,Walmart!C3:C106) -> 0.00036035667 | E28: 1 | F28: =_xlfn.COVARIANCE.S(Walmart!C3:C106,Exxon!C3:C106) -> -1.3863453e-05
A29: Exxon | B29: =_xlfn.COVARIANCE.S(Apple!C3:C106,Exxon!C3:C106) -> 2.8782196e-05 | C29: =_xlfn.COVARIANCE.S(Tesla!C3:C106,Exxon!C3:C106) -> 0.00029010547 | D29: =_xlfn.COVARIANCE.S(Nike!C3:C106,Exxon!C3:C106) -> 6.4783365e-05 | E29: =_xlfn.COVARIANCE.S(Walmart!C3:C106,Exxon!C3:C106) -> -1.3863453e-05 | F29: 1
A31: (Shares Hold^2) x Variansi | B31: Apple | C31: Tesla | D31: Nike | E31: Walmart | F31: Exxon
B32: =(B17^2)*Apple!$C$110 -> 5.2433191e-05 | C32: =(C17^2)*Tesla!$C$110 -> 0.00023288907 | D32: =(D17^2)*Nike!$C$110 -> 7.9730397e-05 | E32: =(E17^2)*Walmart!$C$110 -> 4.1726476e-05 | F32: =(F17^2)*Exxon!$C$110 -> 7.3634249e-05
A34: Shares Hold1 x Shares Hold2 x Covariansi | B34: Apple | C34: Tesla | D34: Nike | E34: Walmart | F34: Exxon
A35: Apple | B35: =(0.2^2)*B25 -> 0.04 | C35: =(0.2^2)*C25 -> 6.010564e-05 | D35: =(0.2^2)*D25 -> 3.2181152e-05 | E35: =(0.2^2)*E25 -> 1.7810181e-05 | F35: =(0.2^2)*F25 -> 1.1512878e-06
A36: Tesla | B36: =(0.2^2)*B26 -> 6.010564e-05 | C36: =(0.2^2)*C26 -> 0.04 | D36: =(0.2^2)*D26 -> 5.2578153e-05 | E36: =(0.2^2)*E26 -> 2.820914e-05 | F36: =(0.2^2)*F26 -> 1.1604219e-05
A37: Nike | B37: =(0.2^2)*B27 -> 3.2181152e-05 | C37: =(0.2^2)*C27 -> 5.2578153e-05 | D37: =(0.2^2)*D27 -> 0.04 | E37: =(0.2^2)*E27 -> 1.4414267e-05 | F37: =(0.2^2)*F27 -> 2.5913346e-06
A38: Walmart | B38: =(0.2^2)*B28 -> 1.7810181e-05 | C38: =(0.2^2)*C28 -> 2.820914e-05 | D38: =(0.2^2)*D28 -> 1.4414267e-05 | E38: =(0.2^2)*E28 -> 0.04 | F38: =(0.2^2)*F28 -> -5.5453813e-07
A39: Exxon | B39: =(0.2^2)*B29 -> 1.1512878e-06 | C39: =(0.2^2)*C29 -> 1.1604219e-05 | D39: =(0.2^2)*D29 -> 2.5913346e-06 | E39: =(0.2^2)*E29 -> -5.5453813e-07 | F39: =(0.2^2)*F29 -> 0.04
A41: Total Portfolio Risk | B41: =SUM(B32:F32)+2*(SUM(B36:B39)+SUM(C37:C39)+SUM(D38:D39)+SUM(E39)) -> 0.00092059505

Sheet MVF
A1: Shares Composition | G1: Portfolio
A2: Shares Composition Sum | B2: Apple (A) | C2: Tesla (B) | D2: Nike (C) | E2: Walmart (D) | F2: Exxon (E) | G2: Risk (sb-x) | H2: Return (sb-y) | J2: Bahan Menhitung Portfolio Risk | M2: Expected Return | P2: solver (Shares^2)*variance | Q2: solver shares*shares*cov | R2: (Shares^2)*variance | S2: shares*shares*cov
A3: =SUM(B3:F3) -> 1 | B3: 1 | C3: 0 | D3: 0 | E3: 0 | F3: 0 | G3: =R3+2*S3 -> 0.0013108298 | H3: =B3*$N$3+C3*$N$4+D3*$N$5+E3*$N$6+F3*$N$7 -> 4.1753523e-05 | J3: Cov A,B | K3: =Portfolio!B26 -> 0.001502641 | M3: Apple | N3: =Portfolio!B15 -> 4.1753523e-05 | P3: =(M22^2)*K13 -> 0 | Q3: =M22*M23*K3 -> 0 | R3: =(B3^2)*$K$13+(C3^2)*$K$14+(D3^2)*$K$15+(E3^2)*$K$16+(F3^2)*K$17 -> 0.0013108298 | S3: =B3*C3*$K$3+B3*D3*$K$4+B3*E3*$K$5+B3*F3*$K$6+C3*D3*$K$7+C3*E3*$K$8+C3*F3*$K$9+D3*E3*$K$10+D3*F3*$K$11+E3*F3*$K$12 -> 0
A4: =SUM(B4:F4) -> 1 | B4: 0.9 | C4: 0.1 | D4: 0 | E4: 0 | F4: 0 | G4: =R4+2*S4 -> 0.0013904698 | H4: =B4*$N$3+C4*$N$4+D4*$N$5+E4*$N$6+F4*$N$7 -> -0.00072126298 | J4: Cov A,C | K4: =Portfolio!B27 -> 0.00080452879 | M4: Tesla | N4: =Portfolio!C15 -> -0.0075884115 | P4: =(M23^2)*K14 -> 0 | Q4: =M22*M24*K4 -> 0 | R4: =(B4^2)*$K$13+(C4^2)*$K$14+(D4^2)*$K$15+(E4^2)*$K$16+(F4^2)*K$17 -> 0.0011199944 | S4: =B4*C4*$K$3+B4*D4*$K$4+B4*E4*$K$5+B4*F4*$K$6+C4*D4*$K$7+C4*E4*$K$8+C4*F4*$K$9+D4*E4*$K$10+D4*F4*$K$11+E4*F4*$K$12 -> 0.00013523769
A5: =SUM(B5:F5) -> 1 | B5: 0.8 | C5: 0.1 | D5: 0.1 | E5: 0 | F5: 0 | G5: =R5+2*S5 -> 0.0013125222 | H5: =B5*$N$3+C5*$N$4+D5*$N$5+E5*$N$6+F5*$N$7 -> -0.00091367557 | J5: Cov A,D | K5: =Portfolio!B28 -> 0.00044525451 | M5: Nike | N5: =Portfolio!D15 -> -0.0018823724 | P5: =(M24^2)*K15 -> 0 | Q5: =M22*M25*K5 -> 0 | R5: =(B5^2)*$K$13+(C5^2)*$K$14+(D5^2)*$K$15+(E5^2)*$K$16+(F5^2)*K$17 -> 0.00091708593 | S5: =B5*C5*$K$3+B5*D5*$K$4+B5*E5*$K$5+B5*F5*$K$6+C5*D5*$K$7+C5*E5*$K$8+C5*F5*$K$9+D5*E5*$K$10+D5*F5*$K$11+E5*F5*$K$12 -> 0.00019771812
A6: =SUM(B6:F6) -> 1 | B6: 0.7 | C6: 0.1 | D6: 0.1 | E6: 0.1 | F6: 0 | G6: =R6+2*S6 -> 0.0011638333 | H6: =B6*$N$3+C6*$N$4+D6*$N$5+E6*$N$6+F6*$N$7 -> -0.00092008856 | J6: Cov A,E | K6: =Portfolio!B29 -> 2.8782196e-05 | M6: Walmart | N6: =Portfolio!E15 -> -2.2376379e-05 | P6: =(M25^2)*K16 -> 1.2878332e-07 | Q6: =M22*M26*K6 -> 0 | R6: =(B6^2)*$K$13+(C6^2)*$K$14+(D6^2)*$K$15+(E6^2)*$K$16+(F6^2)*K$17 -> 0.00073089308 | S6: =B6*C6*$K$3+B6*D6*$K$4+B6*E6*$K$5+B6*F6*$K$6+C6*D6*$K$7+C6*E6*$K$8+C6*F6*$K$9+D6*E6*$K$10+D6*F6*$K$11+E6*F6*$K$12 -> 0.00021647009
A7: =SUM(B7:F7) -> 1 | B7: 0.6 | C7: 0.1 | D7: 0.1 | E7: 0.1 | F7: 0.1 | G7: =R7+2*S7 -> 0.00096705984 | H7: =B7*$N$3+C7*$N$4+D7*$N$5+E7*$N$6+F7*$N$7 -> 3.8037508e-05 | J7: Cov B,C | K7: =Portfolio!C27 -> 0.0013144538 | M7: Exxon | N7: =Portfolio!F15 -> 0.0096230142 | P7: =(M26^2)*K17 -> 0.0018001759 | Q7: =M23*M24*K7 -> 0 | R7: =(B7^2)*$K$13+(C7^2)*$K$14+(D7^2)*$K$15+(E7^2)*$K$16+(F7^2)*K$17 -> 0.00057889377 | S7: =B7*C7*$K$3+B7*D7*$K$4+B7*E7*$K$5+B7*F7*$K$6+C7*D7*$K$7+C7*E7*$K$8+C7*F7*$K$9+D7*E7*$K$10+D7*F7*$K$11+E7*F7*$K$12 -> 0.00019408303
A8: =SUM(B8:F8) -> 1 | B8: 0.5 | C8: 0.2 | D8: 0.1 | E8: 0.1 | F8: 0.1 | G8: =R8+2*S8 -> 0.0011383711 | H8: =B8*$N$3+C8*$N$4+D8*$N$5+E8*$N$6+F8*$N$7 -> -0.00072497899 | J8: Cov B,D | K8: =Portfolio!C28 -> 0.00070522851 | Q8: =M23*M25*K8 -> 0 | R8: =(B8^2)*$K$13+(C8^2)*$K$14+(D8^2)*$K$15+(E8^2)*$K$16+(F8^2)*K$17 -> 0.00060936929 | S8: =B8*C8*$K$3+B8*D8*$K$4+B8*E8*$K$5+B8*F8*$K$6+C8*D8*$K$7+C8*E8*$K$8+C8*F8*$K$9+D8*E8*$K$10+D8*F8*$K$11+E8*F8*$K$12 -> 0.0002645009
A9: =SUM(B9:F9) -> 1 | B9: 0.4 | C9: 0.2 | D9: 0.2 | E9: 0.1 | F9: 0.1 | G9: =R9+2*S9 -> 0.0011199605 | H9: =B9*$N$3+C9*$N$4+D9*$N$5+E9*$N$6+F9*$N$7 -> -0.00091739159 | J9: Cov B,E | K9: =Portfolio!C29 -> 0.00029010547 | Q9: =M23*M26*K9 -> 0 | R9: =(B9^2)*$K$13+(C9^2)*$K$14+(D9^2)*$K$15+(E9^2)*$K$16+(F9^2)*K$17 -> 0.00055119241 | S9: =B9*C9*$K$3+B9*D9*$K$4+B9*E9*$K$5+B9*F9*$K$6+C9*D9*$K$7+C9*E9*$K$8+C9*F9*$K$9+D9*E9*$K$10+D9*F9*$K$11+E9*F9*$K$12 -> 0.00028438405
A10: =SUM(B10:F10) -> 1 | B10: 0.3 | C10: 0.2 | D10: 0.2 | E10: 0.2 | F10: 0.1 | G10: =R10+2*S10 -> 0.0010267912 | H10: =B10*$N$3+C10*$N$4+D10*$N$5+E10*$N$6+F10*$N$7 -> -0.00092380458 | J10: Cov C,D | K10: =Portfolio!D28 -> 0.00036035667 | Q10: =M24*M25*K10 -> 0 | R10: =(B10^2)*$K$13+(C10^2)*$K$14+(D10^2)*$K$15+(E10^2)*$K$16+(F10^2)*K$17 -> 0.00049072918 | S10: =B10*C10*$K$3+B10*D10*$K$4+B10*E10*$K$5+B10*F10*$K$6+C10*D10*$K$7+C10*E10*$K$8+C10*F10*$K$9+D10*E10*$K$10+D10*F10*$K$11+E10*F10*$K$12 -> 0.00026803099
A11: =SUM(B11:F11) -> 1 | B11: 0.2 | C11: 0.2 | D11: 0.2 | E11: 0.2 | F11: 0.2 | G11: =R11+2*S11 -> 0.00092059505 | H11: =B11*$N$3+C11*$N$4+D11*$N$5+E11*$N$6+F11*$N$7 -> 3.4321494e-05 | J11: Cov C,E | K11: =Portfolio!D29 -> 6.4783365e-05 | Q11: =M24*M26*K11 -> 0 | R11: =(B11^2)*$K$13+(C11^2)*$K$14+(D11^2)*$K$15+(E11^2)*$K$16+(F11^2)*K$17 -> 0.00048041338 | S11: =B11*C11*$K$3+B11*D11*$K$4+B11*E11*$K$5+B11*F11*$K$6+C11*D11*$K$7+C11*E11*$K$8+C11*F11*$K$9+D11*E11*$K$10+D11*F11*$K$11+E11*F11*$K$12 -> 0.00022009084
A12: =SUM(B12:F12) -> 1 | B12: 0 | C12: 1 | D12: 0 | E12: 0 | F12: 0 | G12: =R12+2*S12 -> 0.0058222267 | H12: =B12*$N$3+C12*$N$4+D12*$N$5+E12*$N$6+F12*$N$7 -> -0.0075884115 | J12: Cov D,E | K12: =Portfolio!E29 -> -1.3863453e-05 | Q12: =M25*M26*K12 -> -1.5232561e-07 | R12: =(B12^2)*$K$13+(C12^2)*$K$14+(D12^2)*$K$15+(E12^2)*$K$16+(F12^2)*K$17 -> 0.0058222267 | S12: =B12*C12*$K$3+B12*D12*$K$4+B12*E12*$K$5+B12*F12*$K$6+C12*D12*$K$7+C12*E12*$K$8+C12*F12*$K$9+D12*E12*$K$10+D12*F12*$K$11+E12*F12*$K$12 -> 0
A13: =SUM(B13:F13) -> 1 | B13: 0 | C13: 0.9 | D13: 0.1 | E13: 0 | F13: 0 | G13: =R13+2*S13 -> 0.0049725379 | H13: =B13*$N$3+C13*$N$4+D13*$N$5+E13*$N$6+F13*$N$7 -> -0.0070178076 | J13: Var A | K13: =Apple!$C$110 -> 0.0013108298 | R13: =(B13^2)*$K$13+(C13^2)*$K$14+(D13^2)*$K$15+(E13^2)*$K$16+(F13^2)*K$17 -> 0.0047359362 | S13: =B13*C13*$K$3+B13*D13*$K$4+B13*E13*$K$5+B13*F13*$K$6+C13*D13*$K$7+C13*E13*$K$8+C13*F13*$K$9+D13*E13*$K$10+D13*F13*$K$11+E13*F13*$K$12 -> 0.00011830084
A14: =SUM(B14:F14) -> 1 | B14: 0 | C14: 0.8 | D14: 0.1 | E14: 0.1 | F14: 0 | G14: =R14+2*S14 -> 0.0040869456 | H14: =B14*$N$3+C14*$N$4+D14*$N$5+E14*$N$6+F14*$N$7 -> -0.006261204 | J14: Var B | K14: =Tesla!$C$110 -> 0.0058222267 | R14: =(B14^2)*$K$13+(C14^2)*$K$14+(D14^2)*$K$15+(E14^2)*$K$16+(F14^2)*K$17 -> 0.0037565893 | S14: =B14*C14*$K$3+B14*D14*$K$4+B14*E14*$K$5+B14*F14*$K$6+C14*D14*$K$7+C14*E14*$K$8+C14*F14*$K$9+D14*E14*$K$10+D14*F14*$K$11+E14*F14*$K$12 -> 0.00016517815
A15: =SUM(B15:F15) -> 1 | B15: 0 | C15: 0.7 | D15: 0.1 | E15: 0.1 | F15: 0.1 | G15: =R15+2*S15 -> 0.0032332597 | H15: =B15*$N$3+C15*$N$4+D15*$N$5+E15*$N$6+F15*$N$7 -> -0.0045400615 | J15: Var C | K15: =Nike!$C$110 -> 0.0019932599 | R15: =(B15^2)*$K$13+(C15^2)*$K$14+(D15^2)*$K$15+(E15^2)*$K$16+(F15^2)*K$17 -> 0.0029016638 | S15: =B15*C15*$K$3+B15*D15*$K$4+B15*E15*$K$5+B15*F15*$K$6+C15*D15*$K$7+C15*E15*$K$8+C15*F15*$K$9+D15*E15*$K$10+D15*F15*$K$11+E15*F15*$K$12 -> 0.00016579791
A16: =SUM(B16:F16) -> 1 | B16: 0.1 | C16: 0.6 | D16: 0.1 | E16: 0.1 | F16: 0.1 | G16: =R16+2*S16 -> 0.002649171 | H16: =B16*$N$3+C16*$N$4+D16*$N$5+E16*$N$6+F16*$N$7 -> -0.003777045 | J16: Var D | K16: =Walmart!$C$110 -> 0.0010431619 | R16: =(B16^2)*$K$13+(C16^2)*$K$14+(D16^2)*$K$15+(E16^2)*$K$16+(F16^2)*K$17 -> 0.0021578827 | S16: =B16*C16*$K$3+B16*D16*$K$4+B16*E16*$K$5+B16*F16*$K$6+C16*D16*$K$7+C16*E16*$K$8+C16*F16*$K$9+D16*E16*$K$10+D16*F16*$K$11+E16*F16*$K$12 -> 0.00024564415
A17: =SUM(B17:F17) -> 1 | B17: 0.1 | C17: 0.5 | D17: 0.2 | E17: 0.1 | F17: 0.1 | G17: =R17+2*S17 -> 0.002148314 | H17: =B17*$N$3+C17*$N$4+D17*$N$5+E17*$N$6+F17*$N$7 -> -0.0032064411 | J17: Var E | K17: =Exxon!$C$110 -> 0.0018408562 | R17: =(B17^2)*$K$13+(C17^2)*$K$14+(D17^2)*$K$15+(E17^2)*$K$16+(F17^2)*K$17 -> 0.0015772355 | S17: =B17*C17*$K$3+B17*D17*$K$4+B17*E17*$K$5+B17*F17*$K$6+C17*D17*$K$7+C17*E17*$K$8+C17*F17*$K$9+D17*E17*$K$10+D17*F17*$K$11+E17*F17*$K$12 -> 0.00028553924
A18: =SUM(B18:F18) -> 1 | B18: 0.1 | C18: 0.4 | D18: 0.2 | E18: 0.2 | F18: 0.1 | G18: =R18+2*S18 -> 0.0016325312 | H18: =B18*$N$3+C18*$N$4+D18*$N$5+E18*$N$6+F18*$N$7 -> -0.0024498376 | R18: =(B18^2)*$K$13+(C18^2)*$K$14+(D18^2)*$K$15+(E18^2)*$K$16+(F18^2)*K$17 -> 0.00108453 | S18: =B18*C18*$K$3+B18*D18*$K$4+B18*E18*$K$5+B18*F18*$K$6+C18*D18*$K$7+C18*E18*$K$8+C18*F18*$K$9+D18*E18*$K$10+D18*F18*$K$11+E18*F18*$K$12 -> 0.0002740006
A19: =SUM(B19:F19) -> 1 | B19: 0.1 | C19: 0.3 | D19: 0.2 | E19: 0.2 | F19: 0.2 | G19: =R19+2*S19 -> 0.0011835776 | H19: =B19*$N$3+C19*$N$4+D19*$N$5+E19*$N$6+F19*$N$7 -> -0.000728695 | R19: =(B19^2)*$K$13+(C19^2)*$K$14+(D19^2)*$K$15+(E19^2)*$K$16+(F19^2)*K$17 -> 0.00073219982 | S19: =B19*C19*$K$3+B19*D19*$K$4+B19*E19*$K$5+B19*F19*$K$6+C19*D19*$K$7+C19*E19*$K$8+C19*F19*$K$9+D19*E19*$K$10+D19*F19*$K$11+E19*F19*$K$12 -> 0.00022568887
A20: =SUM(B20:F20) -> 1 | B20: 0 | C20: 0 | D20: 1 | E20: 0 | F20: 0 | G20: =R20+2*S20 -> 0.0019932599 | H20: =B20*$N$3+C20*$N$4+D20*$N$5+E20*$N$6+F20*$N$7 -> -0.0018823724 | R20: =(B20^2)*$K$13+(C20^2)*$K$14+(D20^2)*$K$15+(E20^2)*$K$16+(F20^2)*K$17 -> 0.0019932599 | S20: =B20*C20*$K$3+B20*D20*$K$4+B20*E20*$K$5+B20*F20*$K$6+C20*D20*$K$7+C20*E20*$K$8+C20*F20*$K$9+D20*E20*$K$10+D20*F20*$K$11+E20*F20*$K$12 -> 0
A21: =SUM(B21:F21) -> 1 | B21: 0 | C21: 0 | D21: 0.9 | E21: 0.1 | F21: 0 | G21: =R21+2*S21 -> 0.0016898364 | H21: =B21*$N$3+C21*$N$4+D21*$N$5+E21*$N$6+F21*$N$7 -> -0.0016963728 | J21: Bagian Untuk Solver | R21: =(B21^2)*$K$13+(C21^2)*$K$14+(D21^2)*$K$15+(E21^2)*$K$16+(F21^2)*K$17 -> 0.0016249722 | S21: =B21*C21*$K$3+B21*D21*$K$4+B21*E21*$K$5+B21*F21*$K$6+C21*D21*$K$7+C21*E21*$K$8+C21*F21*$K$9+D21*E21*$K$10+D21*F21*$K$11+E21*F21*$K$12 -> 3.24321e-05
A22: =SUM(B22:F22) -> 1 | B22: 0 | C22: 0 | D22: 0.8 | E22: 0.1 | F22: 0.1 | G22: =R22+2*S22 -> 0.0013722717 | H22: =B22*$N$3+C22*$N$4+D22*$N$5+E22*$N$6+F22*$N$7 -> -0.00054583417 | J22: Share Composition Asset A | M22: 0 | R22: =(B22^2)*$K$13+(C22^2)*$K$14+(D22^2)*$K$15+(E22^2)*$K$16+(F22^2)*K$17 -> 0.0013045265 | S22: =B22*C22*$K$3+B22*D22*$K$4+B22*E22*$K$5+B22*F22*$K$6+C22*D22*$K$7+C22*E22*$K$8+C22*F22*$K$9+D22*E22*$K$10+D22*F22*$K$11+E22*F22*$K$12 -> 3.3872568e-05
A23: =SUM(B23:F23) -> 1 | B23: 0.1 | C23: 0 | D23: 0.7 | E23: 0.1 | F23: 0.1 | G23: =R23+2*S23 -> 0.0012000029 | H23: =B23*$N$3+C23*$N$4+D23*$N$5+E23*$N$6+F23*$N$7 -> -0.00035342157 | J23: Share Composition Asset B | M23: 0 | R23: =(B23^2)*$K$13+(C23^2)*$K$14+(D23^2)*$K$15+(E23^2)*$K$16+(F23^2)*K$17 -> 0.0010186458 | S23: =B23*C23*$K$3+B23*D23*$K$4+B23*E23*$K$5+B23*F23*$K$6+C23*D23*$K$7+C23*E23*$K$8+C23*F23*$K$9+D23*E23*$K$10+D23*F23*$K$11+E23*F23*$K$12 -> 9.067855e-05
A24: =SUM(B24:F24) -> 1 | B24: 0.1 | C24: 0.1 | D24: 0.6 | E24: 0.1 | F24: 0.1 | G24: =R24+2*S24 -> 0.001182202 | H24: =B24*$N$3+C24*$N$4+D24*$N$5+E24*$N$6+F24*$N$7 -> -0.00092402547 | J24: Share Composition Asset C | M24: 0 | R24: =(B24^2)*$K$13+(C24^2)*$K$14+(D24^2)*$K$15+(E24^2)*$K$16+(F24^2)*K$17 -> 0.00081774432 | S24: =B24*C24*$K$3+B24*D24*$K$4+B24*E24*$K$5+B24*F24*$K$6+C24*D24*$K$7+C24*E24*$K$8+C24*F24*$K$9+D24*E24*$K$10+D24*F24*$K$11+E24*F24*$K$12 -> 0.00018222884
A25: =SUM(B25:F25) -> 1 | B25: 0.1 | C25: 0.1 | D25: 0.5 | E25: 0.2 | F25: 0.1 | G25: =R25+2*S25 -> 0.0010021239 | H25: =B25*$N$3+C25*$N$4+D25*$N$5+E25*$N$6+F25*$N$7 -> -0.00073802587 | J25: Share Composition Asset D | M25: 0.011111021 | R25: =(B25^2)*$K$13+(C25^2)*$K$14+(D25^2)*$K$15+(E25^2)*$K$16+(F25^2)*K$17 -> 0.00062978058 | S25: =B25*C25*$K$3+B25*D25*$K$4+B25*E25*$K$5+B25*F25*$K$6+C25*D25*$K$7+C25*E25*$K$8+C25*F25*$K$9+D25*E25*$K$10+D25*F25*$K$11+E25*F25*$K$12 -> 0.00018617164
A26: =SUM(B26:F26) -> 1 | B26: 0.1 | C26: 0.1 | D26: 0.4 | E26: 0.2 | F26: 0.2 | G26: =R26+2*S26 -> 0.00083087246 | H26: =B26*$N$3+C26*$N$4+D26*$N$5+E26*$N$6+F26*$N$7 -> 0.0004125128 | J26: Share Composition Asset E | M26: 0.98888898 | R26: =(B26^2)*$K$13+(C26^2)*$K$14+(D26^2)*$K$15+(E26^2)*$K$16+(F26^2)*K$17 -> 0.00050561288 | S26: =B26*C26*$K$3+B26*D26*$K$4+B26*E26*$K$5+B26*F26*$K$6+C26*D26*$K$7+C26*E26*$K$8+C26*F26*$K$9+D26*E26*$K$10+D26*F26*$K$11+E26*F26*$K$12 -> 0.00016262979
A27: =SUM(B27:F27) -> 1 | B27: 0.2 | C27: 0.1 | D27: 0.3 | E27: 0.2 | F27: 0.2 | G27: =R27+2*S27 -> 0.00076856992 | H27: =B27*$N$3+C27*$N$4+D27*$N$5+E27*$N$6+F27*$N$7 -> 0.0006049254 | J27: Total Composition | M27: =SUM(M22:M26) -> 1 | R27: =(B27^2)*$K$13+(C27^2)*$K$14+(D27^2)*$K$15+(E27^2)*$K$16+(F27^2)*K$17 -> 0.00040540958 | S27: =B27*C27*$K$3+B27*D27*$K$4+B27*E27*$K$5+B27*F27*$K$6+C27*D27*$K$7+C27*E27*$K$8+C27*F27*$K$9+D27*E27*$K$10+D27*F27*$K$11+E27*F27*$K$12 -> 0.00018158017
A28: =SUM(B28:F28) -> 1 | B28: 0 | C28: 0 | D28: 0 | E28: 1 | F28: 0 | G28: =R28+2*S28 -> 0.0010431619 | H28: =B28*$N$3+C28*$N$4+D28*$N$5+E28*$N$6+F28*$N$7 -> -2.2376379e-05 | R28: =(B28^2)*$K$13+(C28^2)*$K$14+(D28^2)*$K$15+(E28^2)*$K$16+(F28^2)*K$17 -> 0.0010431619 | S28: =B28*C28*$K$3+B28*D28*$K$4+B28*E28*$K$5+B28*F28*$K$6+C28*D28*$K$7+C28*E28*$K$8+C28*F28*$K$9+D28*E28*$K$10+D28*F28*$K$11+E28*F28*$K$12 -> 0
A29: =SUM(B29:F29) -> 1 | B29: 0 | C29: 0 | D29: 0 | E29: 0.9 | F29: 0.1 | G29: =R29+2*S29 -> 0.00086087427 | H29: =B29*$N$3+C29*$N$4+D29*$N$5+E29*$N$6+F29*$N$7 -> 0.00094216268 | J29: Portfolio Return | M29: =(M22^2)*N3+(M23^2)*N4+(M24^2)*N5+(M25^2)*N6+(M26^2)*N7 -> 0.0094103564 | R29: =(B29^2)*$K$13+(C29^2)*$K$14+(D29^2)*$K$15+(E29^2)*$K$16+(F29^2)*K$17 -> 0.00086336969 | S29: =B29*C29*$K$3+B29*D29*$K$4+B29*E29*$K$5+B29*F29*$K$6+C29*D29*$K$7+C29*E29*$K$8+C29*F29*$K$9+D29*E29*$K$10+D29*F29*$K$11+E29*F29*$K$12 -> -1.2477108e-06
A30: =SUM(B30:F30) -> 1 | B30: 0.1 | C30: 0 | D30: 0 | E30: 0.8 | F30: 0.1 | G30: =R30+2*S30 -> 0.00076873868 | H30: =B30*$N$3+C30*$N$4+D30*$N$5+E30*$N$6+F30*$N$7 -> 0.00094857567 | J30: Portfolio Risk | M30: =(M22^2)*$K$13+(M23^2)*$K$14+(M24^2)*$K$15+(M25^2)*$K$16+(M26^2)*$K$17+2*(M22*M23*K3+M22*M24*K4+M22*M25*K5+M22*M26*K6+M23*M24*K7+M23*M25*K8+M23*M26*K9+M24*M25*K10+M24*M26*K11+M25*M26*K12) -> 0.0018 | R30: =(B30^2)*$K$13+(C30^2)*$K$14+(D30^2)*$K$15+(E30^2)*$K$16+(F30^2)*K$17 -> 0.00069914047 | S30: =B30*C30*$K$3+B30*D30*$K$4+B30*E30*$K$5+B30*F30*$K$6+C30*D30*$K$7+C30*E30*$K$8+C30*F30*$K$9+D30*E30*$K$10+D30*F30*$K$11+E30*F30*$K$12 -> 3.4799107e-05
A31: =SUM(B31:F31) -> 1 | B31: 0.1 | C31: 0.1 | D31: 0 | E31: 0.7 | F31: 0.1 | G31: =R31+2*S31 -> 0.00079644577 | H31: =B31*$N$3+C31*$N$4+D31*$N$5+E31*$N$6+F31*$N$7 -> 0.00019197216 | R31: =(B31^2)*$K$13+(C31^2)*$K$14+(D31^2)*$K$15+(E31^2)*$K$16+(F31^2)*K$17 -> 0.00060088845 | S31: =B31*C31*$K$3+B31*D31*$K$4+B31*E31*$K$5+B31*F31*$K$6+C31*D31*$K$7+C31*E31*$K$8+C31*F31*$K$9+D31*E31*$K$10+D31*F31*$K$11+E31*F31*$K$12 -> 9.7778656e-05
A32: =SUM(B32:F32) -> 1 | B32: 0.1 | C32: 0.1 | D32: 0.1 | E32: 0.6 | F32: 0.1 | G32: =R32+2*S32 -> 0.00074495305 | H32: =B32*$N$3+C32*$N$4+D32*$N$5+E32*$N$6+F32*$N$7 -> 5.9725573e-06 | R32: =(B32^2)*$K$13+(C32^2)*$K$14+(D32^2)*$K$15+(E32^2)*$K$16+(F32^2)*K$17 -> 0.00048521001 | S32: =B32*C32*$K$3+B32*D32*$K$4+B32*E32*$K$5+B32*F32*$K$6+C32*D32*$K$7+C32*E32*$K$8+C32*F32*$K$9+D32*E32*$K$10+D32*F32*$K$11+E32*F32*$K$12 -> 0.00012987152
A33: =SUM(B33:F33) -> 1 | B33: 0.1 | C33: 0.1 | D33: 0.1 | E33: 0.5 | F33: 0.2 | G33: =R33+2*S33 -> 0.00066177848 | H33: =B33*$N$3+C33*$N$4+D33*$N$5+E33*$N$6+F33*$N$7 -> 0.00097051162 | J33: Kasus 1 | R33: =(B33^2)*$K$13+(C33^2)*$K$14+(D33^2)*$K$15+(E33^2)*$K$16+(F33^2)*K$17 -> 0.00042568789 | S33: =B33*C33*$K$3+B33*D33*$K$4+B33*E33*$K$5+B33*F33*$K$6+C33*D33*$K$7+C33*E33*$K$8+C33*F33*$K$9+D33*E33*$K$10+D33*F33*$K$11+E33*F33*$K$12 -> 0.0001180453
A34: =SUM(B34:F34) -> 1 | B34: 0.2 | C34: 0.1 | D34: 0.1 | E34: 0.4 | F34: 0.2 | G34: =R34+2*S34 -> 0.00066047159 | H34: =B34*$N$3+C34*$N$4+D34*$N$5+E34*$N$6+F34*$N$7 -> 0.00097692461 | J34: Maximize Return (f. objektif) | M34: 0.0094103564 | R34: =(B34^2)*$K$13+(C34^2)*$K$14+(D34^2)*$K$15+(E34^2)*$K$16+(F34^2)*K$17 -> 0.00037112821 | S34: =B34*C34*$K$3+B34*D34*$K$4+B34*E34*$K$5+B34*F34*$K$6+C34*D34*$K$7+C34*E34*$K$8+C34*F34*$K$9+D34*E34*$K$10+D34*F34*$K$11+E34*F34*$K$12 -> 0.00014467169
A35: =SUM(B35:F35) -> 1 | B35: 0.2 | C35: 0.2 | D35: 0.1 | E35: 0.3 | F35: 0.2 | G35: =R35+2*S35 -> 0.00086386236 | H35: =B35*$N$3+C35*$N$4+D35*$N$5+E35*$N$6+F35*$N$7 -> 0.0002203211 | J35: Given Risk (f. kendala) | M35: 0.0018 | R35: =(B35^2)*$K$13+(C35^2)*$K$14+(D35^2)*$K$15+(E35^2)*$K$16+(F35^2)*K$17 -> 0.00047277368 | S35: =B35*C35*$K$3+B35*D35*$K$4+B35*E35*$K$5+B35*F35*$K$6+C35*D35*$K$7+C35*E35*$K$8+C35*F35*$K$9+D35*E35*$K$10+D35*F35*$K$11+E35*F35*$K$12 -> 0.00019554434
A36: =SUM(B36:F36) -> 1 | B36: 0 | C36: 0 | D36: 0 | E36: 0 | F36: 1 | G36: =R36+2*S36 -> 0.0018408562 | H36: =B36*$N$3+C36*$N$4+D36*$N$5+E36*$N$6+F36*$N$7 -> 0.0096230142 | R36: =(B36^2)*$K$13+(C36^2)*$K$14+(D36^2)*$K$15+(E36^2)*$K$16+(F36^2)*K$17 -> 0.0018408562 | S36: =B36*C36*$K$3+B36*D36*$K$4+B36*E36*$K$5+B36*F36*$K$6+C36*D36*$K$7+C36*E36*$K$8+C36*F36*$K$9+D36*E36*$K$10+D36*F36*$K$11+E36*F36*$K$12 -> 0
A37: =SUM(B37:F37) -> 1 | B37: 0.1 | C37: 0 | D37: 0 | E37: 0 | F37: 0.9 | G37: =R37+2*S37 -> 0.0015093826 | H37: =B37*$N$3+C37*$N$4+D37*$N$5+E37*$N$6+F37*$N$7 -> 0.0086648882 | J37: Kasus 2 | R37: =(B37^2)*$K$13+(C37^2)*$K$14+(D37^2)*$K$15+(E37^2)*$K$16+(F37^2)*K$17 -> 0.0015042018 | S37: =B37*C37*$K$3+B37*D37*$K$4+B37*E37*$K$5+B37*F37*$K$6+C37*D37*$K$7+C37*E37*$K$8+C37*F37*$K$9+D37*E37*$K$10+D37*F37*$K$11+E37*F37*$K$12 -> 2.5903976e-06
A38: =SUM(B38:F38) -> 1 | B38: 0.1 | C38: 0.1 | D38: 0 | E38: 0 | F38: 0.8 | G38: =R38+2*S38 -> 0.0013305534 | H38: =B38*$N$3+C38*$N$4+D38*$N$5+E38*$N$6+F38*$N$7 -> 0.0069437456 | J38: Given Return (f. kendala) | M38: 0.0059999997 | R38: =(B38^2)*$K$13+(C38^2)*$K$14+(D38^2)*$K$15+(E38^2)*$K$16+(F38^2)*K$17 -> 0.0012494786 | S38: =B38*C38*$K$3+B38*D38*$K$4+B38*E38*$K$5+B38*F38*$K$6+C38*D38*$K$7+C38*E38*$K$8+C38*F38*$K$9+D38*E38*$K$10+D38*F38*$K$11+E38*F38*$K$12 -> 4.0537423e-05
A39: =SUM(B39:F39) -> 1 | B39: 0.1 | C39: 0.1 | D39: 0.1 | E39: 0 | F39: 0.7 | G39: =R39+2*S39 -> 0.0011194291 | H39: =B39*$N$3+C39*$N$4+D39*$N$5+E39*$N$6+F39*$N$7 -> 0.0057932069 | J39: Minimize Risk (f. objektif) | M39: 0.0011834701 | R39: =(B39^2)*$K$13+(C39^2)*$K$14+(D39^2)*$K$15+(E39^2)*$K$16+(F39^2)*K$17 -> 0.00099328272 | S39: =B39*C39*$K$3+B39*D39*$K$4+B39*E39*$K$5+B39*F39*$K$6+C39*D39*$K$7+C39*E39*$K$8+C39*F39*$K$9+D39*E39*$K$10+D39*F39*$K$11+E39*F39*$K$12 -> 6.3073209e-05
A40: =SUM(B40:F40) -> 1 | B40: 0.1 | C40: 0.1 | D40: 0.1 | E40: 0.1 | F40: 0.6 | G40: =R40+2*S40 -> 0.0009114292 | H40: =B40*$N$3+C40*$N$4+D40*$N$5+E40*$N$6+F40*$N$7 -> 0.0048286679 | R40: =(B40^2)*$K$13+(C40^2)*$K$14+(D40^2)*$K$15+(E40^2)*$K$16+(F40^2)*K$17 -> 0.00076440303 | S40: =B40*C40*$K$3+B40*D40*$K$4+B40*E40*$K$5+B40*F40*$K$6+C40*D40*$K$7+C40*E40*$K$8+C40*F40*$K$9+D40*E40*$K$10+D40*F40*$K$11+E40*F40*$K$12 -> 7.3513088e-05
...

Sheet CAL CML SML
A1: Risk Free (per tahun) | B1: Risk Free (per minggu)
A2: 0.07148 | B2: =A2/52 -> 0.0013746154
A4: CAL (Melewati MVF)
A5: ambil komposisi
A6: Apple | B6: Tesla | C6: Nike | D6: Walmart | E6: Exxon
A7: 0.1 | B7: 0.1 | C7: 0.1 | D7: 0.5 | E7: 0.2
A9: 2 titik yang dilewati
A10: x (risk) | B10: y (return) | C10: slope (beta)
A11: 0 | B11: =B2 -> 0.0013746154
A12: 0.00066177848 | B12: 0.00097051162 | C12: =(B12-B11)/(A12-A11) -> -0.61063299
A14: Persamaan Garis
A15: y = 0,001374615 + (-6,1063)*x
A17: plot titik
A18: x (risk) | B18: y (return)
A19: 0 | B19: =$B$2+$C$12*A19 -> 0.0013746154
A20: 0.0001 | B20: =$B$2+$C$12*A20 -> 0.0013135521
A21: 0.0006 | B21: =$B$2+$C$12*A21 -> 0.0010082356
A22: 0.001 | B22: =$B$2+$C$12*A22 -> 0.0007639824
A23: 0.0065 | B23: =$B$2+$C$12*A23 -> -0.002594499
A32: CML (Tepat Menyinggung MVF)
A33: Calon Titik Singgung (diliat dari gambar)
A34: x (risk) | B34: y (return) | C34: slope | I34: 0 | J34: 0 | K34: 0 | L34: 0 | M34: 1 | N34: 0.0018408562 | O34: 0.0096230142
A35: 0 | B35: 0.001374615 | I35: 0.1 | J35: 0 | K35: 0 | L35: 0 | M35: 0.9 | N35: 0.0015093826 | O35: 0.0086648882
A36: 0.0018408562 | B36: 0.0096230142 | C36: =(B36-$B$35)/(A36-$A$35) -> 4.4807406
A37: 0.0015093826 | B37: 0.0086648882 | C37: =(B37-$B$35)/(A37-$A$35) -> 4.8299702 | D37: (ambil yang slope paling besar)
A39: Persamaan Garis
A40: y = 0,001374615 +4,829970184*x
A42: plot titik
A43: x (risk) | B43: y (return)
A44: 0 | B44: =$B$2+$C$37*A44 -> 0.0013746154
A45: 0.0005 | B45: =$B$2+$C$37*A45 -> 0.0037896005
A46: 0.001 | B46: =$B$2+$C$37*A46 -> 0.0062045856
A47: 0.0015 | B47: =$B$2+$C$37*A47 -> 0.0086195707
A48: 0.005 | B48: =$B$2+$C$37*A48 -> 0.025524466
A49: 0.0065 | B49: =$B$2+$C$37*A49 -> 0.032769422
A59: SML
A60: 2 titik yang dilewati
A61: x (beta) | B61: y (return) | C61: slope
A62: 0 | B62: =$B$2+$C$36*A62 -> 0.0013746154
A63: 1 | B63: 0.0086648882 | C63: =(B63-B62)/(A63-A62) -> 0.0072902728
...
